<?xml version="1.0"?>
<!-- http://wiki.ros.org/urdf/XML/link -->
<robot name="simples_robot">
    <!-- Link 1-->
    <link name="base_link">
        <visual>
            <geometry>
                <cylinder length="0.05" radius="0.2"/>
            </geometry>
			<!-- Origem: o quadro de referência do elemento visual em relação ao quadro de referência do link  -->
			<!-- Angulos rpy - roll, pitch e yaw  -->
			<!-- Eixos xyz -->
			<origin rpy="0 0 0" xyz="0 0 0"/>
            <!-- Sem rotações e deslocamentos -->
			<material name="yellow">
				<color rgba="1 1 0 1"/>
			</material>
        </visual>
    </link>

    <!-- Junta 1 -->
    <joint name = "joint_1" type = "revolute">
        <parent link = "base_link"/>  <!-- Link 1: Base -->
        <child  link = "first_link"/> <!-- Link 2:  -->
        <origin xyz = "0 0 0.025"/>    <!-- Origem em xy = 0 e z =0.25 -->
        <axis   xyz = "0 0 1"/>       <!-- Rotaciona em Z -->
        <limit effort   = "300"
               velocity = "2.0"
               lower    = "-1.2"
               upper    = "1.7"/>
    </joint>  

    <!-- Link 2-->
    <link name="first_link">
        <visual>
            <geometry>
                <cylinder length="0.5" radius="0.04"/>
            </geometry>
			<!-- Origem: o quadro de referência do elemento visual em relação ao quadro de referência do link  -->
			<!-- Angulos rpy - roll, pitch e yaw  -->
			<!-- Eixos xyz -->
			<origin rpy="0 0 0" xyz="0 0 0.25"/>
            <!-- Sem rotações e deslocamentos -->
			<material name="red">
				<color rgba="0 0 1 1"/>
			</material>
        </visual>
    </link>

     <!-- Junta 2 -->
    <joint name = "joint_2" type = "prismatic">
        <parent link = "first_link"/>  <!-- Link 2: -->
        <child  link = "second_link"/> <!-- Link 3: -->
        <origin xyz = "0 0 0.5"/>    <!-- Origem em xy = 0 e z =0.5 -->
        <axis   xyz = "0 1 0"/>       <!-- Rotaciona em y -->
        <limit effort   = "300"
               velocity = "2.0"
               lower    = "-5"
               upper    = "5"/>
    </joint> 

    <!-- Link 3-->
    <link name="second_link">
        <visual>
            <geometry>
                <box size = "0.1 1 0.1"/>
            </geometry>
			<!-- Origem: o quadro de referência do elemento visual em relação ao quadro de referência do link  -->
			<!-- Angulos rpy - roll, pitch e yaw  -->
			<!-- Eixos xyz -->
			<origin rpy="0 0 0" xyz="0 0 0.05"/>
            <!-- Sem rotações e deslocamentos -->
			<material name="blue">
				<color rgba="0 1 0 1"/>
			</material>
        </visual>
    </link> 

</robot>